Workbook
Name SupplierNameList: 供应商管理!$C$2:$C$1000

Sheet 指标看板
A1: 临时工管理指标看板 v3
J2: 分析起始日期 | K2: 46174 | L2: ← 修改此日期刷新分析 | AB2: 周度分析
AB3: 起始日期 | AC3: 2026-06-01
A4: 面试总人数 | C4: 面试通过率 | E4: 报到率 | G4: 当前在职人数
A5: =COUNTA(面试清单!C:C)-1 -> 3631 | C5: =IFERROR(COUNTIF(面试清单!I:I,"通过")/(COUNTA(面试清单!I:I)-1),0) -> 0.45166621 | E5: =IFERROR(COUNTIF(面试清单!J:J,"是")/COUNTIF(面试清单!I:I,"通过"),0) -> 0.60487805 | G5: {=SUMPRODUCT(--(LEN(在职清单!$G:$G)>0))-1} -> 3831 | AB5: 周次 | AC5: 起始 | AD5: 结束 | AE5: 入职 | AF5: 离职 | AG5: 净增
A6: 累计入职人数 | C6: 累计离职人数 | E6: 当月入职 | G6: 当月离职 | AB6: W1 | AC6: =IF($AC$3="","",$AC$3+(1-1)*7) -> 46174 | AD6: =IF($AC6="","",$AC6+6) -> 46180 | AE6: =IF($AC6="","",COUNTIFS(面试清单!K:K,">="&$AC6,面试清单!K:K,"<="&$AD6,面试清单!J:J,"是")) -> 346 | AF6: =IF($AC6="","",COUNTIFS(离职清单!H:H,">="&$AC6,离职清单!H:H,"<="&$AD6)) -> 204 | AG6: =IF($AC6="","",AE6-AF6) -> 142
A7: =COUNTIF(面试清单!J:J,"是") -> 992 | C7: =COUNTA(离职清单!B:B)-1 -> 474 | AB7: W2 | AC7: =IF($AC$3="","",$AC$3+(2-1)*7) -> 46181 | AD7: =IF($AC7="","",$AC7+6) -> 46187 | AE7: =IF($AC7="","",COUNTIFS(面试清单!K:K,">="&$AC7,面试清单!K:K,"<="&$AD7,面试清单!J:J,"是")) -> 563 | AF7: =IF($AC7="","",COUNTIFS(离职清单!H:H,">="&$AC7,离职清单!H:H,"<="&$AD7)) -> 216 | AG7: =IF($AC7="","",AE7-AF7) -> 347
AB8: W3 | AC8: =IF($AC$3="","",$AC$3+(3-1)*7) -> 46188 | AD8: =IF($AC8="","",$AC8+6) -> 46194 | AE8: =IF($AC8="","",COUNTIFS(面试清单!K:K,">="&$AC8,面试清单!K:K,"<="&$AD8,面试清单!J:J,"是")) -> 21 | AF8: =IF($AC8="","",COUNTIFS(离职清单!H:H,">="&$AC8,离职清单!H:H,"<="&$AD8)) -> 0 | AG8: =IF($AC8="","",AE8-AF8) -> 21
A9: 【新增】总目标达成表 | AB9: W4 | AC9: =IF($AC$3="","",$AC$3+(4-1)*7) -> 46195 | AD9: =IF($AC9="","",$AC9+6) -> 46201 | AE9: =IF($AC9="","",COUNTIFS(面试清单!K:K,">="&$AC9,面试清单!K:K,"<="&$AD9,面试清单!J:J,"是")) -> 0 | AF9: =IF($AC9="","",COUNTIFS(离职清单!H:H,">="&$AC9,离职清单!H:H,"<="&$AD9)) -> 0 | AG9: =IF($AC9="","",AE9-AF9) -> 0
A10: 区域 | B10: 目标 | C10: 净增 | D10: 缺口 | E10: 净增达成率
A11: 江门 | B11: 150 | C11: =COUNTIFS(面试清单!N:N,"江门",面试清单!K:K,">="&$K$2,面试清单!J:J,"是")-COUNTIFS(离职清单!N:N,"江门",离职清单!H:H,">="&$K$2) -> 311 | D11: =MAX(0,B11-C11) -> 0 | E11: =IFERROR(C11/B11,0) -> 2.0733333
A12: 成都 | B12: 90 | C12: =COUNTIFS(面试清单!N:N,"成都",面试清单!K:K,">="&$K$2,面试清单!J:J,"是")-COUNTIFS(离职清单!N:N,"成都",离职清单!H:H,">="&$K$2) -> 199 | D12: =MAX(0,B12-C12) -> 0 | E12: =IFERROR(C12/B12,0) -> 2.2111111
A13: 汇总 | B13: =SUM(B11:B12) -> 240 | C13: =SUM(C11:C12) -> 510 | D13: =SUM(D11:D12) -> 0 | E13: =IFERROR(C13/B13,0) -> 2.125
A15: 【新增】周日度明细表（区域 x 工种）
A16: 区域 | B16: 工种 | C16: 本周累计 入职 | D16: 本周累计 离职 | E16: 本周累计 净增长 | F16: 今日在职 | G16: =IF($K$2="","",TEXT($K$2+0,"M/D")) -> 6/1 | J16: =IF($K$2="","",TEXT($K$2+1,"M/D")) -> 6/2 | M16: =IF($K$2="","",TEXT($K$2+2,"M/D")) -> 6/3 | P16: =IF($K$2="","",TEXT($K$2+3,"M/D")) -> 6/4 | S16: =IF($K$2="","",TEXT($K$2+4,"M/D")) -> 6/5 | V16: =IF($K$2="","",TEXT($K$2+5,"M/D")) -> 6/6 | Y16: =IF($K$2="","",TEXT($K$2+6,"M/D")) -> 6/7
G17: 入 | H17: 离 | I17: 净 | J17: 入 | K17: 离 | L17: 净 | M17: 入 | N17: 离 | O17: 净 | P17: 入 | Q17: 离 | R17: 净 | S17: 入 | T17: 离 | U17: 净 | V17: 入 | W17: 离 | X17: 净 | Y17: 入 | Z17: 离 | AA17: 净
A18: 江门 | B18: 电工 | C18: =COUNTIFS(面试清单!$N:$N,"江门",面试清单!$E:$E,"电工",面试清单!$K:$K,">="&$K$2,面试清单!$J:$J,"是") -> 355 | D18: =COUNTIFS(离职清单!$N:$N,"江门",离职清单!$D:$D,"电工",离职清单!$H:$H,">="&$K$2) -> 101 | E18: =C18-D18 -> 254 | F18: =COUNTIFS(面试清单!N:N,"江门",面试清单!E:E,"电工",面试清单!O:O,"在职",面试清单!J:J,"是") -> 391 | G18: =COUNTIFS(面试清单!$N:$N,"江门",面试清单!$E:$E,"电工",面试清单!$K:$K,G$16,面试清单!$J:$J,"是") -> 5 | H18: =COUNTIFS(离职清单!$N:$N,"江门",离职清单!$D:$D,"电工",离职清单!$H:$H,G$16) -> 8 | I18: =G18-H18 -> -3 | J18: =COUNTIFS(面试清单!$N:$N,"江门",面试清单!$E:$E,"电工",面试清单!$K:$K,J$16,面试清单!$J:$J,"是") -> 12 | K18: =COUNTIFS(离职清单!$N:$N,"江门",离职清单!$D:$D,"电工",离职清单!$H:$H,J$16) -> 1 | L18: =J18-K18 -> 11 | M18: =COUNTIFS(面试清单!$N:$N,"江门",面试清单!$E:$E,"电工",面试清单!$K:$K,M$16,面试清单!$J:$J,"是") -> 16 | N18: =COUNTIFS(离职清单!$N:$N,"江门",离职清单!$D:$D,"电工",离职清单!$H:$H,M$16) -> 1 | O18: =M18-N18 -> 15 | P18: =COUNTIFS(面试清单!$N:$N,"江门",面试清单!$E:$E,"电工",面试清单!$K:$K,P$16,面试清单!$J:$J,"是") -> 9 | Q18: =COUNTIFS(离职清单!$N:$N,"江门",离职清单!$D:$D,"电工",离职清单!$H:$H,P$16) -> 22 | R18: =P18-Q18 -> -13 | S18: =COUNTIFS(面试清单!$N:$N,"江门",面试清单!$E:$E,"电工",面试清单!$K:$K,S$16,面试清单!$J:$J,"是") -> 26 | T18: =COUNTIFS(离职清单!$N:$N,"江门",离职清单!$D:$D,"电工",离职清单!$H:$H,S$16) -> 8 | U18: =S18-T18 -> 18 | V18: =COUNTIFS(面试清单!$N:$N,"江门",面试清单!$E:$E,"电工",面试清单!$K:$K,V$16,面试清单!$J:$J,"是") -> 28 | W18: =COUNTIFS(离职清单!$N:$N,"江门",离职清单!$D:$D,"电工",离职清单!$H:$H,V$16) -> 0 | X18: =V18-W18 -> 28 | Y18: =COUNTIFS(面试清单!$N:$N,"江门",面试清单!$E:$E,"电工",面试清单!$K:$K,Y$16,面试清单!$J:$J,"是") -> 24 | Z18: =COUNTIFS(离职清单!$N:$N,"江门",离职清单!$D:$D,"电工",离职清单!$H:$H,Y$16) -> 0 | AA18: =Y18-Z18 -> 24
B19: 钳工 | C19: =COUNTIFS(面试清单!$N:$N,"江门",面试清单!$E:$E,"钳工",面试清单!$K:$K,">="&$K$2,面试清单!$J:$J,"是") -> 205 | D19: =COUNTIFS(离职清单!$N:$N,"江门",离职清单!$D:$D,"钳工",离职清单!$H:$H,">="&$K$2) -> 113 | E19: =C19-D19 -> 92 | F19: =COUNTIFS(面试清单!N:N,"江门",面试清单!E:E,"钳工",面试清单!O:O,"在职",面试清单!J:J,"是") -> 229 | G19: =COUNTIFS(面试清单!$N:$N,"江门",面试清单!$E:$E,"钳工",面试清单!$K:$K,G$16,面试清单!$J:$J,"是") -> 3 | H19: =COUNTIFS(离职清单!$N:$N,"江门",离职清单!$D:$D,"钳工",离职清单!$H:$H,G$16) -> 13 | I19: =G19-H19 -> -10 | J19: =COUNTIFS(面试清单!$N:$N,"江门",面试清单!$E:$E,"钳工",面试清单!$K:$K,J$16,面试清单!$J:$J,"是") -> 5 | K19: =COUNTIFS(离职清单!$N:$N,"江门",离职清单!$D:$D,"钳工",离职清单!$H:$H,J$16) -> 5 | L19: =J19-K19 -> 0 | M19: =COUNTIFS(面试清单!$N:$N,"江门",面试清单!$E:$E,"钳工",面试清单!$K:$K,M$16,面试清单!$J:$J,"是") -> 4 | N19: =COUNTIFS(离职清单!$N:$N,"江门",离职清单!$D:$D,"钳工",离职清单!$H:$H,M$16) -> 5 | O19: =M19-N19 -> -1 | P19: =COUNTIFS(面试清单!$N:$N,"江门",面试清单!$E:$E,"钳工",面试清单!$K:$K,P$16,面试清单!$J:$J,"是") -> 7 | Q19: =COUNTIFS(离职清单!$N:$N,"江门",离职清单!$D:$D,"钳工",离职清单!$H:$H,P$16) -> 20 | R19: =P19-Q19 -> -13 | S19: =COUNTIFS(面试清单!$N:$N,"江门",面试清单!$E:$E,"钳工",面试清单!$K:$K,S$16,面试清单!$J:$J,"是") -> 5 | T19: =COUNTIFS(离职清单!$N:$N,"江门",离职清单!$D:$D,"钳工",离职清单!$H:$H,S$16) -> 17 | U19: =S19-T19 -> -12 | V19: =COUNTIFS(面试清单!$N:$N,"江门",面试清单!$E:$E,"钳工",面试清单!$K:$K,V$16,面试清单!$J:$J,"是") -> 18 | W19: =COUNTIFS(离职清单!$N:$N,"江门",离职清单!$D:$D,"钳工",离职清单!$H:$H,V$16) -> 0 | X19: =V19-W19 -> 18 | Y19: =COUNTIFS(面试清单!$N:$N,"江门",面试清单!$E:$E,"钳工",面试清单!$K:$K,Y$16,面试清单!$J:$J,"是") -> 12 | Z19: =COUNTIFS(离职清单!$N:$N,"江门",离职清单!$D:$D,"钳工",离职清单!$H:$H,Y$16) -> 0 | AA19: =Y19-Z19 -> 12
B20: 合计 | C20: =SUM(C18:C19) -> 560 | D20: =SUM(D18:D19) -> 214 | E20: =C20-D20 -> 346 | F20: =SUM(F18:F19) -> 620 | G20: =SUM(G18:G19) -> 8 | H20: =SUM(H18:H19) -> 21 | I20: =G20-H20 -> -13 | J20: =SUM(J18:J19) -> 17 | K20: =SUM(K18:K19) -> 6 | L20: =J20-K20 -> 11 | M20: =SUM(M18:M19) -> 20 | N20: =SUM(N18:N19) -> 6 | O20: =M20-N20 -> 14 | P20: =SUM(P18:P19) -> 16 | Q20: =SUM(Q18:Q19) -> 42 | R20: =P20-Q20 -> -26 | S20: =SUM(S18:S19) -> 31 | T20: =SUM(T18:T19) -> 25 | U20: =S20-T20 -> 6 | V20: =SUM(V18:V19) -> 46 | W20: =SUM(W18:W19) -> 0 | X20: =V20-W20 -> 46 | Y20: =SUM(Y18:Y19) -> 36 | Z20: =SUM(Z18:Z19) -> 0 | AA20: =Y20-Z20 -> 36
A21: 成都 | B21: 电工 | C21: =COUNTIFS(面试清单!$N:$N,"成都",面试清单!$E:$E,"电工",面试清单!$K:$K,">="&$K$2,面试清单!$J:$J,"是") -> 144 | D21: =COUNTIFS(离职清单!$N:$N,"成都",离职清单!$D:$D,"电工",离职清单!$H:$H,">="&$K$2) -> 11 | E21: =C21-D21 -> 133 | F21: =COUNTIFS(面试清单!N:N,"成都",面试清单!E:E,"电工",面试清单!O:O,"在职",面试清单!J:J,"是") -> 144 | G21: =COUNTIFS(面试清单!$N:$N,"成都",面试清单!$E:$E,"电工",面试清单!$K:$K,G$16,面试清单!$J:$J,"是") -> 6 | H21: =COUNTIFS(离职清单!$N:$N,"成都",离职清单!$D:$D,"电工",离职清单!$H:$H,G$16) -> 1 | I21: =G21-H21 -> 5 | J21: =COUNTIFS(面试清单!$N:$N,"成都",面试清单!$E:$E,"电工",面试清单!$K:$K,J$16,面试清单!$J:$J,"是") -> 3 | K21: =COUNTIFS(离职清单!$N:$N,"成都",离职清单!$D:$D,"电工",离职清单!$H:$H,J$16) -> 1 | L21: =J21-K21 -> 2 | M21: =COUNTIFS(面试清单!$N:$N,"成都",面试清单!$E:$E,"电工",面试清单!$K:$K,M$16,面试清单!$J:$J,"是") -> 15 | N21: =COUNTIFS(离职清单!$N:$N,"成都",离职清单!$D:$D,"电工",离职清单!$H:$H,M$16) -> 0 | O21: =M21-N21 -> 15 | P21: =COUNTIFS(面试清单!$N:$N,"成都",面试清单!$E:$E,"电工",面试清单!$K:$K,P$16,面试清单!$J:$J,"是") -> 16 | Q21: =COUNTIFS(离职清单!$N:$N,"成都",离职清单!$D:$D,"电工",离职清单!$H:$H,P$16) -> 1 | R21: =P21-Q21 -> 15 | S21: =COUNTIFS(面试清单!$N:$N,"成都",面试清单!$E:$E,"电工",面试清单!$K:$K,S$16,面试清单!$J:$J,"是") -> 21 | T21: =COUNTIFS(离职清单!$N:$N,"成都",离职清单!$D:$D,"电工",离职清单!$H:$H,S$16) -> 0 | U21: =S21-T21 -> 21 | V21: =COUNTIFS(面试清单!$N:$N,"成都",面试清单!$E:$E,"电工",面试清单!$K:$K,V$16,面试清单!$J:$J,"是") -> 13 | W21: =COUNTIFS(离职清单!$N:$N,"成都",离职清单!$D:$D,"电工",离职清单!$H:$H,V$16) -> 0 | X21: =V21-W21 -> 13 | Y21: =COUNTIFS(面试清单!$N:$N,"成都",面试清单!$E:$E,"电工",面试清单!$K:$K,Y$16,面试清单!$J:$J,"是") -> 5 | Z21: =COUNTIFS(离职清单!$N:$N,"成都",离职清单!$D:$D,"电工",离职清单!$H:$H,Y$16) -> 0 | AA21: =Y21-Z21 -> 5
B22: 钳工 | C22: =COUNTIFS(面试清单!$N:$N,"成都",面试清单!$E:$E,"钳工",面试清单!$K:$K,">="&$K$2,面试清单!$J:$J,"是") -> 112 | D22: =COUNTIFS(离职清单!$N:$N,"成都",离职清单!$D:$D,"钳工",离职清单!$H:$H,">="&$K$2) -> 46 | E22: =C22-D22 -> 66 | F22: =COUNTIFS(面试清单!N:N,"成都",面试清单!E:E,"钳工",面试清单!O:O,"在职",面试清单!J:J,"是") -> 112 | G22: =COUNTIFS(面试清单!$N:$N,"成都",面试清单!$E:$E,"钳工",面试清单!$K:$K,G$16,面试清单!$J:$J,"是") -> 4 | H22: =COUNTIFS(离职清单!$N:$N,"成都",离职清单!$D:$D,"钳工",离职清单!$H:$H,G$16) -> 8 | I22: =G22-H22 -> -4 | J22: =COUNTIFS(面试清单!$N:$N,"成都",面试清单!$E:$E,"钳工",面试清单!$K:$K,J$16,面试清单!$J:$J,"是") -> 3 | K22: =COUNTIFS(离职清单!$N:$N,"成都",离职清单!$D:$D,"钳工",离职清单!$H:$H,J$16) -> 2 | L22: =J22-K22 -> 1 | M22: =COUNTIFS(面试清单!$N:$N,"成都",面试清单!$E:$E,"钳工",面试清单!$K:$K,M$16,面试清单!$J:$J,"是") -> 5 | N22: =COUNTIFS(离职清单!$N:$N,"成都",离职清单!$D:$D,"钳工",离职清单!$H:$H,M$16) -> 0 | O22: =M22-N22 -> 5 | P22: =COUNTIFS(面试清单!$N:$N,"成都",面试清单!$E:$E,"钳工",面试清单!$K:$K,P$16,面试清单!$J:$J,"是") -> 9 | Q22: =COUNTIFS(离职清单!$N:$N,"成都",离职清单!$D:$D,"钳工",离职清单!$H:$H,P$16) -> 6 | R22: =P22-Q22 -> 3 | S22: =COUNTIFS(面试清单!$N:$N,"成都",面试清单!$E:$E,"钳工",面试清单!$K:$K,S$16,面试清单!$J:$J,"是") -> 12 | T22: =COUNTIFS(离职清单!$N:$N,"成都",离职清单!$D:$D,"钳工",离职清单!$H:$H,S$16) -> 0 | U22: =S22-T22 -> 12 | V22: =COUNTIFS(面试清单!$N:$N,"成都",面试清单!$E:$E,"钳工",面试清单!$K:$K,V$16,面试清单!$J:$J,"是") -> 6 | W22: =COUNTIFS(离职清单!$N:$N,"成都",离职清单!$D:$D,"钳工",离职清单!$H:$H,V$16) -> 0 | X22: =V22-W22 -> 6 | Y22: =COUNTIFS(面试清单!$N:$N,"成都",面试清单!$E:$E,"钳工",面试清单!$K:$K,Y$16,面试清单!$J:$J,"是") -> 8 | Z22: =COUNTIFS(离职清单!$N:$N,"成都",离职清单!$D:$D,"钳工",离职清单!$H:$H,Y$16) -> 0 | AA22: =Y22-Z22 -> 8
B23: 合计 | C23: =SUM(C21:C22) -> 256 | D23: =SUM(D21:D22) -> 57 | E23: =C23-D23 -> 199 | F23: =SUM(F21:F22) -> 256 | G23: =SUM(G21:G22) -> 10 | H23: =SUM(H21:H22) -> 9 | I23: =G23-H23 -> 1 | J23: =SUM(J21:J22) -> 6 | K23: =SUM(K21:K22) -> 3 | L23: =J23-K23 -> 3 | M23: =SUM(M21:M22) -> 20 | N23: =SUM(N21:N22) -> 0 | O23: =M23-N23 -> 20 | P23: =SUM(P21:P22) -> 25 | Q23: =SUM(Q21:Q22) -> 7 | R23: =P23-Q23 -> 18 | S23: =SUM(S21:S22) -> 33 | T23: =SUM(T21:T22) -> 0 | U23: =S23-T23 -> 33 | V23: =SUM(V21:V22) -> 19 | W23: =SUM(W21:W22) -> 0 | X23: =V23-W23 -> 19 | Y23: =SUM(Y21:Y22) -> 13 | Z23: =SUM(Z21:Z22) -> 0 | AA23: =Y23-Z23 -> 13
A24: 总计 | C24: =SUM(C20,C23) -> 816 | D24: =SUM(D20,D23) -> 271 | E24: =SUM(E20,E23) -> 545 | F24: =SUM(F20,F23) -> 876 | G24: =SUM(G20,G23) -> 18 | H24: =SUM(H20,H23) -> 30 | I24: =SUM(I20,I23) -> -12 | J24: =SUM(J20,J23) -> 23 | ... AA24: =SUM(AA20,AA23) -> 49
A26: 人员结构分析报告（数据截止： | G26: =TEXT(TODAY(),"YYYY年M月D日") -> 2026年6月16日 | I26: )没有选定日期时，默认截止今天
A27: 在职人数 | D27: 起始日起总需求 | G27: 累计招聘人数 | J27: 当前缺口人数
A28: {=SUMPRODUCT(--(LEN(在职清单!$G:$G)>0))-1-COUNTIFS(在职清单!$G:$G,">"&$G$26)} -> 3831 | D28: 240 | G28: =COUNTIF(面试清单!$J:$J,"是")-COUNTIFS(面试清单!$J:$J,"是",面试清单!$K:$K,">"&$G$26) -> 992 | J28: =D28-(G28-COUNTIFS(离职清单!$H:$H,"<="&$G$26)) -> -278
A30: 大工 / 中工 / 小工 — 四维度占比分析
A31: 等级 | B31: 在职人数 | C31: 在职占比 | D31: 需求 | E31: 需求占比 | F31: 招聘完成率 | G31: 缺口数量 | H31: 缺口占比 | I31: 满足率 | J31: 紧急度 | L31: {=SUMPRODUCT(--(LEN(面试清单!$P:$P)>0))-1} -> 992
A32: 大工 | B32: =COUNTIFS(在职清单!$E:$E,$A32) -> 1637 | C32: {=IFERROR($B32/(SUMPRODUCT(--(LEN(在职清单!$B:$B)>0))-1),0)} -> 0.42730358 | D32: 0 | E32: =IFERROR(D32/SUM($D$32:$D$34),0) -> 0 | F32: =IFERROR(B32/D32,0) -> 0 | G32: =MAX(0,D32-B32) -> 0 | H32: =IFERROR(G32/SUM($G$32:$G$34),0) -> 0 | I32: =IFERROR(B32/D32,0) -> 0 | J32: =IF(H32>=0.5,"高",IF(H32>=0.2,"中","低")) -> 低
A33: 中工 | B33: =COUNTIFS(在职清单!$E:$E,$A33) -> 1321 | C33: {=IFERROR($B33/(SUMPRODUCT(--(LEN(在职清单!$B:$B)>0))-1),0)} -> 0.34481859 | D33: 0 | E33: =IFERROR(D33/SUM($D$32:$D$34),0) -> 0 | F33: =IFERROR(B33/D33,0) -> 0 | G33: =MAX(0,D33-B33) -> 0 | H33: =IFERROR(G33/SUM($G$32:$G$34),0) -> 0 | I33: =IFERROR(B33/D33,0) -> 0 | J33: =IF(H33>=0.5,"高",IF(H33>=0.2,"中","低")) -> 低
A34: 小工 | B34: =COUNTIFS(在职清单!$E:$E,$A34) -> 800 | C34: {=IFERROR($B34/(SUMPRODUCT(--(LEN(在职清单!$B:$B)>0))-1),0)} -> 0.20882276 | D34: 0 | E34: =IFERROR(D34/SUM($D$32:$D$34),0) -> 0 | F34: =IFERROR(B34/D34,0) -> 0 | G34: =MAX(0,D34-B34) -> 0 | H34: =IFERROR(G34/SUM($G$32:$G$34),0) -> 0 | I34: =IFERROR(B34/D34,0) -> 0 | J34: =IF(H34>=0.5,"高",IF(H34>=0.2,"中","低")) -> 低
A35: 合计 | B35: =SUM(B32:B34) -> 3758 | C35: =100% -> 1 | D35: =SUM(D32:D34) -> 0 | E35: =100% -> 1 | F35: =IFERROR(B35/D35,0) -> 0 | G35: =SUM(G32:G34) -> 0 | H35: =100% -> 1 | I35: =IFERROR(B35/D35,0) -> 0 | J35: -
A37: 电工 / 钳工 — 工种维度对比
A38: 工种 | B38: 在职人数 | C38: 在职占比 | D38: 需求 | E38: 需求占比 | F38: 招聘完成率 | G38: 缺口 | H38: 占总缺口比 | I38: 紧急度
A39: 电工 | B39: =COUNTIFS(面试清单!E:E,"电工",面试清单!P:P,"<>") -> 2085 | C39: =IFERROR(B39/COUNTIF(面试清单!P:P,"<>"),0) -> 0.42980829 | D39: 0 | E39: =IFERROR(D39/SUM($D$39:$D$40),0) -> 0 | F39: =IFERROR(B39/D39,0) -> 0 | G39: =MAX(0,D39-B39) -> 0 | H39: =IFERROR(G39/SUM($G$39:$G$40),0) -> 0 | I39: =IF(H39>0.5,"高",IF(H39>0,"中","充足")) -> 充足
A40: 钳工 | B40: =COUNTIFS(面试清单!E:E,"钳工",面试清单!P:P,"<>") -> 1253 | C40: =IFERROR(B40/COUNTIF(面试清单!P:P,"<>"),0) -> 0.25829726 | D40: 0 | E40: =IFERROR(D40/SUM($D$39:$D$40),0) -> 0 | F40: =IFERROR(B40/D40,0) -> 0 | G40: =MAX(0,D40-B40) -> 0 | H40: =IFERROR(G40/SUM($G$39:$G$40),0) -> 0 | I40: =IF(H40>0.5,"高",IF(H40>0,"中","充足")) -> 充足
A41: 合计 | B41: =SUM(B39:B40) -> 3338 | C41: =100% -> 1 | D41: =SUM(D39:D40) -> 0 | E41: =100% -> 1 | F41: =IFERROR(B41/D41,0) -> 0 | G41: =SUM(G39:G40) -> 0 | H41: =100% -> 1 | I41: -
A43: 四、按岗位类型统计
A44: 岗位类型 | B44: 在职人数 | C44: 累计入职 | D44: 累计离职 | E44: 占比
A45: 电工 | B45: =COUNTIFS(面试清单!E:E,"电工",面试清单!P:P,"<>") -> 2085 | C45: =COUNTIFS(面试清单!E:E,"电工",面试清单!J:J,"是") -> 535 | D45: =COUNTIF(离职清单!D:D,"电工") -> 125 | E45: =IFERROR(B45/COUNTIF(面试清单!P:P,"<>"),0) -> 0.42980829
...

Sheet 面试清单
A1: 序号 | B1: 面试日期 | C1: 姓名 | D1: 身份证后四位 | E1: 岗位类型 | F1: 技能等级 | G1: 供应商 | H1: 面试渠道 | I1: 面试结果 | J1: 是否报到 | K1: 报到日期 | L1: 联系人电话 | M1: 备注 | N1: 地区 | O1: 离职状态(辅助) | P1: 在职序号(辅助)
A2: =IF(B2<>"",ROW()-1,"") -> 1 | B2: 46174 | C2: 黄鹏云 | D2: 0002 | E2: 电工 | F2: 大工 | G2: 共辉 | H2: 线下 | I2: 通过 | J2: 否 | K2: 46174 | N2: 江门 | O2: =IF(D2="","",IF(COUNTIF(离职清单!C:C,D2)>0,"已离职","在职")) -> 在职 | P2: =IF(AND(O2="在职",J2="是"),COUNTIF(O$2:O2,"在职"),"")
A3: =IF(B3<>"",ROW()-1,"") -> 2 | B3: 46174 | C3: 何岸兰 | D3: 0003 | E3: 电工 | F3: 小工 | G3: 共辉 | H3: 线下 | I3: 通过 | J3: 否 | K3: 46174 | N3: 江门 | O3: =IF(D3="","",IF(COUNTIF(离职清单!C:C,D3)>0,"已离职","在职")) -> 在职 | P3: =IF(AND(O3="在职",J3="是"),COUNTIF(O$2:O3,"在职"),"")
A4: =IF(B4<>"",ROW()-1,"") -> 3 | B4: 46174 | C4: 梁永康 | D4: 0004 | E4: 电工 | F4: 小工 | G4: 慧城 | H4: 线下 | I4: 不通过 | J4: 否 | K4: 46174 | N4: 江门 | O4: =IF(D4="","",IF(COUNTIF(离职清单!C:C,D4)>0,"已离职","在职")) -> 在职 | P4: =IF(AND(O4="在职",J4="是"),COUNTIF(O$2:O4,"在职"),"")
A5: =IF(B5<>"",ROW()-1,"") -> 4 | B5: 46174 | C5: 曹书豪 | D5: 0005 | E5: 电工 | F5: 小工 | G5: 慧城 | H5: 线下 | I5: 通过 | J5: 是 | K5: 46174 | N5: 江门 | O5: =IF(D5="","",IF(COUNTIF(离职清单!C:C,D5)>0,"已离职","在职")) -> 在职 | P5: =IF(AND(O5="在职",J5="是"),COUNTIF(O$2:O5,"在职"),"") -> 4
A6: =IF(B6<>"",ROW()-1,"") -> 5 | B6: 46174 | C6: 蓝枫 | D6: 0006 | E6: 电工 | F6: 小工 | G6: 智邦 | H6: 线下 | I6: 通过 | J6: 是 | K6: 46174 | N6: 江门 | O6: =IF(D6="","",IF(COUNTIF(离职清单!C:C,D6)>0,"已离职","在职")) -> 在职 | P6: =IF(AND(O6="在职",J6="是"),COUNTIF(O$2:O6,"在职"),"") -> 5
A7: =IF(B7<>"",ROW()-1,"") -> 6 | B7: 46174 | C7: 唐嘉 | D7: 0007 | E7: 钳工 | F7: 小工 | G7: 智邦 | H7: 线下 | I7: 不通过 | J7: 否 | K7: 46174 | N7: 江门 | O7: =IF(D7="","",IF(COUNTIF(离职清单!C:C,D7)>0,"已离职","在职")) -> 在职 | P7: =IF(AND(O7="在职",J7="是"),COUNTIF(O$2:O7,"在职"),"")
A8: =IF(B8<>"",ROW()-1,"") -> 7 | B8: 46174 | C8: 陶召健 | D8: 0008 | E8: 电工 | F8: 小工 | G8: 智邦 | H8: 线下 | I8: 不通过 | J8: 否 | K8: 46174 | N8: 江门 | O8: =IF(D8="","",IF(COUNTIF(离职清单!C:C,D8)>0,"已离职","在职")) -> 在职 | P8: =IF(AND(O8="在职",J8="是"),COUNTIF(O$2:O8,"在职"),"")
A9: =IF(B9<>"",ROW()-1,"") -> 8 | B9: 46174 | C9: 陈峰真 | D9: 0009 | E9: 钳工 | F9: 中工 | G9: 慧通 | H9: 线下 | I9: 通过 | J9: 是 | K9: 46174 | N9: 江门 | O9: =IF(D9="","",IF(COUNTIF(离职清单!C:C,D9)>0,"已离职","在职")) -> 在职 | P9: =IF(AND(O9="在职",J9="是"),COUNTIF(O$2:O9,"在职"),"") -> 8
A10: =IF(B10<>"",ROW()-1,"") -> 9 | B10: 46174 | C10: 莫振旺 | D10: 0010 | E10: 钳工 | F10: 小工 | G10: 慧通 | H10: 线下 | I10: 不通过 | J10: 否 | K10: 46174 | N10: 江门 | O10: =IF(D10="","",IF(COUNTIF(离职清单!C:C,D10)>0,"已离职","在职")) -> 已离职 | P10: =IF(AND(O10="在职",J10="是"),COUNTIF(O$2:O10,"在职"),"")
A11: =IF(B11<>"",ROW()-1,"") -> 10 | B11: 46174 | C11: 刘玉龙 | D11: 0011 | E11: 电工 | F11: 小工 | G11: 赞华 | H11: 线下 | I11: 不通过 | J11: 否 | K11: 46174 | N11: 江门 | O11: =IF(D11="","",IF(COUNTIF(离职清单!C:C,D11)>0,"已离职","在职")) -> 已离职 | P11: =IF(AND(O11="在职",J11="是"),COUNTIF(O$2:O11,"在职"),"")
A12: =IF(B12<>"",ROW()-1,"") -> 11 | B12: 46174 | C12: 李君朋 | D12: 0012 | E12: 钳工 | F12: 中工 | G12: 杰威 | H12: 线下 | I12: 通过 | J12: 否 | K12: 46174 | N12: 江门 | O12: =IF(D12="","",IF(COUNTIF(离职清单!C:C,D12)>0,"已离职","在职")) -> 在职 | P12: =IF(AND(O12="在职",J12="是"),COUNTIF(O$2:O12,"在职"),"")
A13: =IF(B13<>"",ROW()-1,"") -> 12 | B13: 46174 | C13: 赖建丞 | D13: 0013 | E13: 仓库 | F13: 小工 | G13: 华伟 | H13: 线下 | I13: 通过 | J13: 是 | K13: 46174 | N13: 江门 | O13: =IF(D13="","",IF(COUNTIF(离职清单!C:C,D13)>0,"已离职","在职")) -> 在职 | P13: =IF(AND(O13="在职",J13="是"),COUNTIF(O$2:O13,"在职"),"") -> 10
... A917: =IF(B917<>"",ROW()-1,"") -> 916 | B917: 46187 | C917: 梁勇 | D917: 0212 | E917: 电工 | F917: 小工 | G917: 聘得宝 | H917: 线下 | I917: 不通过 | J917: 否 | K917: 46187 | N917: 江门 | O917: =IF(D917="","",IF(COUNTIF(离职清单!C:C,D917)>0,"已离职","在职")) -> 在职 | P917: =IF(AND(O917="在职",J917="是"),COUNTIF(O$2:O917,"在职"),"")
A918: =IF(B918<>"",ROW()-1,"") -> 917 | B918: 46174 | C918: 虞志友 | D918: 0214 | E918: 钳工 | F918: 中工 | G918: 技为 | H918: 线上 | I918: 通过 | J918: 否 | N918: 江门 | O918: =IF(D918="","",IF(COUNTIF(离职清单!C:C,D918)>0,"已离职","在职")) -> 在职 | P918: =IF(AND(O918="在职",J918="是"),COUNTIF(O$2:O918,"在职"),"")
A919: =IF(B919<>"",ROW()-1,"") -> 918 | B919: 46174 | C919: 严传玖 | D919: 0217 | E919: 钳工 | F919: 中工 | G919: 技为 | H919: 线上 | I919: 通过 | J919: 否 | N919: 江门 | O919: =IF(D919="","",IF(COUNTIF(离职清单!C:C,D919)>0,"已离职","在职")) -> 在职 | P919: =IF(AND(O919="在职",J919="是"),COUNTIF(O$2:O919,"在职"),"")
A920: =IF(B920<>"",ROW()-1,"") -> 919 | B920: 46174 | C920: 喻龙 | D920: 0218 | E920: 钳工 | F920: 小工 | G920: 技为 | H920: 线上 | I920: 通过 | J920: 否 | N920: 江门 | O920: =IF(D920="","",IF(COUNTIF(离职清单!C:C,D920)>0,"已离职","在职")) -> 在职 | P920: =IF(AND(O920="在职",J920="是"),COUNTIF(O$2:O920,"在职"),"")
A921: =IF(B921<>"",ROW()-1,"") -> 920 | B921: 46174 | C921: 唐仕斌 | D921: 0220 | E921: 钳工 | F921: 大工 | G921: 技为 | H921: 线上 | I921: 通过 | J921: 是 | K921: 46176 | N921: 江门 | O921: =IF(D921="","",IF(COUNTIF(离职清单!C:C,D921)>0,"已离职","在职")) -> 在职 | P921: =IF(AND(O921="在职",J921="是"),COUNTIF(O$2:O921,"在职"),"") -> 914
A922: =IF(B922<>"",ROW()-1,"") -> 921 | B922: 46174 | C922: 汤智略 | D922: 0221 | E922: 钳工 | F922: 小工 | G922: 创信达 | H922: 线上 | I922: 通过 | J922: 否 | N922: 江门 | O922: =IF(D922="","",IF(COUNTIF(离职清单!C:C,D922)>0,"已离职","在职")) -> 在职 | P922: =IF(AND(O922="在职",J922="是"),COUNTIF(O$2:O922,"在职"),"")
A923: =IF(B923<>"",ROW()-1,"") -> 922 | B923: 46174 | C923: 陈山旗 | D923: 0222 | E923: 钳工 | F923: 小工 | G923: 技为 | H923: 线上 | I923: 通过 | J923: 否 | N923: 江门 | O923: =IF(D923="","",IF(COUNTIF(离职清单!C:C,D923)>0,"已离职","在职")) -> 在职 | P923: =IF(AND(O923="在职",J923="是"),COUNTIF(O$2:O923,"在职"),"")
A924: =IF(B924<>"",ROW()-1,"") -> 923 | B924: 46174 | C924: 李帅 | D924: 0208 | E924: 钳工 | F924: 大工 | G924: 赞华 | H924: 线上 | I924: 通过 | J924: 否 | N924: 江门 | O924: =IF(D924="","",IF(COUNTIF(离职清单!C:C,D924)>0,"已离职","在职")) -> 在职 | P924: =IF(AND(O924="在职",J924="是"),COUNTIF(O$2:O924,"在职"),"")
A925: =IF(B925<>"",ROW()-1,"") -> 924 | B925: 46174 | C925: 任晓飞 | D925: 0209 | E925: 钳工 | F925: 大工 | G925: 科为 | H925: 线上 | I925: 通过 | J925: 否 | K925: 46176 | N925: 江门 | O925: =IF(D925="","",IF(COUNTIF(离职清单!C:C,D925)>0,"已离职","在职")) -> 在职 | P925: =IF(AND(O925="在职",J925="是"),COUNTIF(O$2:O925,"在职"),"")
A926: =IF(B926<>"",ROW()-1,"") -> 925 | B926: 46174 | C926: 骆双红 | D926: 0212 | E926: 钳工 | F926: 中工 | G926: 奕晨 | H926: 线上 | I926: 通过 | J926: 是 | K926: 46175 | N926: 江门 | O926: =IF(D926="","",IF(COUNTIF(离职清单!C:C,D926)>0,"已离职","在职")) -> 在职 | P926: =IF(AND(O926="在职",J926="是"),COUNTIF(O$2:O926,"在职"),"") -> 919
A927: =IF(B927<>"",ROW()-1,"") -> 926 | B927: 46174 | C927: 张惠敏 | D927: 0214 | E927: 钳工 | F927: 大工 | G927: 赞华 | H927: 线上 | I927: 通过 | J927: 否 | K927: 46175 | N927: 江门 | O927: =IF(D927="","",IF(COUNTIF(离职清单!C:C,D927)>0,"已离职","在职")) -> 在职 | P927: =IF(AND(O927="在职",J927="是"),COUNTIF(O$2:O927,"在职"),"")
A928: =IF(B928<>"",ROW()-1,"") -> 927 | B928: 46174 | C928: 乐黎武 | D928: 0217 | E928: 钳工 | F928: 小工 | G928: 智邦 | H928: 线上 | I928: 通过 | J928: 否 | N928: 江门 | O928: =IF(D928="","",IF(COUNTIF(离职清单!C:C,D928)>0,"已离职","在职")) -> 在职 | P928: =IF(AND(O928="在职",J928="是"),COUNTIF(O$2:O928,"在职"),"")
A929: =IF(B929<>"",ROW()-1,"") -> 928 | B929: 46174 | C929: 封宏瀚 | D929: 0218 | E929: 钳工 | F929: 大工 | G929: 慧通 | H929: 线上 | I929: 通过 | J929: 否 | K929: 46175 | N929: 江门 | O929: =IF(D929="","",IF(COUNTIF(离职清单!C:C,D929)>0,"已离职","在职")) -> 在职 | P929: =IF(AND(O929="在职",J929="是"),COUNTIF(O$2:O929,"在职"),"")
A930: =IF(B930<>"",ROW()-1,"") -> 929 | B930: 46174 | C930: 李金华 | D930: 0220 | E930: 钳工 | F930: 中工 | G930: 慧通 | H930: 线上 | I930: 通过 | J930: 否 | K930: 46175 | N930: 江门 | O930: =IF(D930="","",IF(COUNTIF(离职清单!C:C,D930)>0,"已离职","在职")) -> 在职 | P930: =IF(AND(O930="在职",J930="是"),COUNTIF(O$2:O930,"在职"),"")
A931: =IF(B931<>"",ROW()-1,"") -> 930 | B931: 46174 | C931: 李顺杰 | D931: 0221 | E931: 钳工 | F931: 大工 | G931: 赞华 | H931: 线上 | I931: 通过 | J931: 否 | N931: 江门 | O931: =IF(D931="","",IF(COUNTIF(离职清单!C:C,D931)>0,"已离职","在职")) -> 在职 | P931: =IF(AND(O931="在职",J931="是"),COUNTIF(O$2:O931,"在职"),"")
A932: =IF(B932<>"",ROW()-1,"") -> 931 | B932: 46174 | C932: 黄宜冰 | D932: 0222 | E932: 钳工 | F932: 中工 | G932: 赞华 | H932: 线上 | I932: 通过 | J932: 否 | N932: 江门 | O932: =IF(D932="","",IF(COUNTIF(离职清单!C:C,D932)>0,"已离职","在职")) -> 在职 | P932: =IF(AND(O932="在职",J932="是"),COUNTIF(O$2:O932,"在职"),"")
A933: =IF(B933<>"",ROW()-1,"") -> 932 | B933: 46174 | C933: 张鸿茂 | D933: 0208 | E933: 钳工 | F933: 中工 | G933: 赞华 | H933: 线上 | I933: 通过 | J933: 否 | K933: 46175 | N933: 江门 | O933: =IF(D933="","",IF(COUNTIF(离职清单!C:C,D933)>0,"已离职","在职")) -> 在职 | P933: =IF(AND(O933="在职",J933="是"),COUNTIF(O$2:O933,"在职"),"")
A934: =IF(B934<>"",ROW()-1,"") -> 933 | B934: 46174 | C934: 汪哲 | D934: 0209 | E934: 钳工 | F934: 中工 | G934: 赞华 | H934: 线上 | I934: 通过 | J934: 否 | N934: 江门 | O934: =IF(D934="","",IF(COUNTIF(离职清单!C:C,D934)>0,"已离职","在职")) -> 在职 | P934: =IF(AND(O934="在职",J934="是"),COUNTIF(O$2:O934,"在职"),"")
A935: =IF(B935<>"",ROW()-1,"") -> 934 | B935: 46174 | C935: 林添仁 | D935: 0212 | E935: 钳工 | F935: 大工 | G935: 杰威 | H935: 线上 | I935: 通过 | J935: 否 | K935: 46176 | N935: 江门 | O935: =IF(D935="","",IF(COUNTIF(离职清单!C:C,D935)>0,"已离职","在职")) -> 在职 | P935: =IF(AND(O935="在职",J935="是"),COUNTIF(O$2:O935,"在职"),"")
A936: =IF(B936<>"",ROW()-1,"") -> 935 | B936: 46174 | C936: 陈历文 | D936: 0214 | E936: 钳工 | F936: 大工 | G936: 杰威 | H936: 线上 | I936: 通过 | J936: 否 | N936: 江门 | O936: =IF(D936="","",IF(COUNTIF(离职清单!C:C,D936)>0,"已离职","在职")) -> 在职 | P936: =IF(AND(O936="在职",J936="是"),COUNTIF(O$2:O936,"在职"),"")
A937: =IF(B937<>"",ROW()-1,"") -> 936 | B937: 46174 | C937: 陈毅 | D937: 0217 | E937: 钳工 | F937: 大工 | G937: 杰威 | H937: 线上 | I937: 通过 | J937: 否 | N937: 江门 | O937: =IF(D937="","",IF(COUNTIF(离职清单!C:C,D937)>0,"已离职","在职")) -> 在职 | P937: =IF(AND(O937="在职",J937="是"),COUNTIF(O$2:O937,"在职"),"")
A938: =IF(B938<>"",ROW()-1,"") -> 937 | B938: 46174 | C938: 肖体刚 | D938: 0218 | E938: 钳工 | F938: 中工 | G938: 薪向往 | H938: 线上 | I938: 通过 | J938: 是 | K938: 46175 | N938: 江门 | O938: =IF(D938="","",IF(COUNTIF(离职清单!C:C,D938)>0,"已离职","在职")) -> 在职 | P938: =IF(AND(O938="在职",J938="是"),COUNTIF(O$2:O938,"在职"),"") -> 931
A939: =IF(B939<>"",ROW()-1,"") -> 938 | B939: 46174 | C939: 李腾飞 | D939: 0220 | E939: 钳工 | F939: 中工 | G939: 薪向往 | H939: 线上 | I939: 通过 | J939: 否 | K939: 46175 | N939: 江门 | O939: =IF(D939="","",IF(COUNTIF(离职清单!C:C,D939)>0,"已离职","在职")) -> 在职 | P939: =IF(AND(O939="在职",J939="是"),COUNTIF(O$2:O939,"在职"),"")
A940: =IF(B940<>"",ROW()-1,"") -> 939 | B940: 46174 | C940: 付义龙 | D940: 0221 | E940: 钳工 | F940: 大工 | G940: 科为 | H940: 线上 | I940: 通过 | J940: 是 | K940: 46176 | N940: 江门 | O940: =IF(D940="","",IF(COUNTIF(离职清单!C:C,D940)>0,"已离职","在职")) -> 在职 | P940: =IF(AND(O940="在职",J940="是"),COUNTIF(O$2:O940,"在职"),"") -> 933
A941: =IF(B941<>"",ROW()-1,"") -> 940 | B941: 46174 | C941: 时旺旺 | D941: 0222 | E941: 钳工 | F941: 中工 | G941: 技为 | H941: 线上 | I941: 通过 | J941: 否 | N941: 江门 | O941: =IF(D941="","",IF(COUNTIF(离职清单!C:C,D941)>0,"已离职","在职")) -> 在职 | P941: =IF(AND(O941="在职",J941="是"),COUNTIF(O$2:O941,"在职"),"")
A942: =IF(B942<>"",ROW()-1,"") -> 941 | B942: 46174 | C942: 田进 | D942: 0208 | E942: 钳工 | F942: 中工 | G942: 技为 | H942: 线上 | I942: 通过 | J942: 否 | N942: 江门 | O942: =IF(D942="","",IF(COUNTIF(离职清单!C:C,D942)>0,"已离职","在职")) -> 在职 | P942: =IF(AND(O942="在职",J942="是"),COUNTIF(O$2:O942,"在职"),"")
A943: =IF(B943<>"",ROW()-1,"") -> 942 | B943: 46174 | C943: 周斌斌 | D943: 0209 | E943: 钳工 | F943: 中工 | G943: 技为 | H943: 线上 | I943: 通过 | J943: 否 | N943: 江门 | O943: =IF(D943="","",IF(COUNTIF(离职清单!C:C,D943)>0,"已离职","在职")) -> 在职 | P943: =IF(AND(O943="在职",J943="是"),COUNTIF(O$2:O943,"在职"),"")
...

Sheet 供应商管理
A1: 序号 | B1: 供应商编号 | C1: 供应商名称 | D1: 联系人 | E1: 联系电话 | F1: 备注
A2: =IF(B2<>"",ROW()-1,"") -> 1 | B2: 001 | C2: 智服 | D2: 王晓利 | E2: 18616121191 | F2: 成都
A3: =IF(B3<>"",ROW()-1,"") -> 2 | B3: 002 | C3: 源栋 | D3: 苏航宇 | E3: 18525855059 | F3: 成都
A4: =IF(B4<>"",ROW()-1,"") -> 3 | B4: 003 | C4: 同创 | D4: 吴霞 | E4: 19082465687 | F4: 成都
A5: =IF(B5<>"",ROW()-1,"") -> 4 | B5: 004 | C5: 奕晨 | D5: 周培 | E5: 13420092107 | F5: 成都
A6: =IF(B6<>"",ROW()-1,"") -> 5 | B6: 005 | C6: 天贤途 | D6: 吴小龙 | E6: 19382251875 | F6: 成都
A7: =IF(B7<>"",ROW()-1,"") -> 6 | B7: 006 | C7: 科为 | D7: 都建飞 | E7: 13544889449 | F7: 成都
A8: =IF(B8<>"",ROW()-1,"") -> 7 | B8: 007 | C8: 汇天浩 | D8: 杨琼 | E8: 13241499001 | F8: 成都
A9: =IF(B9<>"",ROW()-1,"") -> 8 | B9: 008 | C9: 赞华 | D9: 陈青山 | E9: 18695918302 | F9: 成都
A10: =IF(B10<>"",ROW()-1,"") -> 9 | B10: 009 | C10: 优蓝 | D10: 向津兴 | E10: 17608120464 | F10: 成都
A11: =IF(B11<>"",ROW()-1,"") -> 10 | B11: 010 | C11: 善道 | D11: 夏永宏 | E11: 13515273937 | F11: 成都
A12: =IF(B12<>"",ROW()-1,"") -> 11 | B12: 011 | C12: 创享 | D12: 杨希昊 | E12: 18615750377 | F12: 成都
A13: =IF(B13<>"",ROW()-1,"") -> 12 | B13: 012 | C13: 东棠 | D13: 陈瑶 | E13: 17738869707 | F13: 成都
... A51: =IF(B51<>"",ROW()-1,"") -> 50 | B51: 050 | C51: 华聘 | D51: 周永尊 | E51: 17841564693 | F51: 江门
B52: 051 | C52: 淘金 | D52: 黄文龙 | E52: 18675546135 | F52: 江门
B53: 052 | C53: 智保 | D53: 谢惠竹 | E53: 18688695239 | F53: 江门
B54: 053 | C54: 人多多 | D54: 董师 | E54: 13510450317 | F54: 江门
B55: 054 | C55: 宇成 | D55: 代俊成 | E55: 13649862577 | F55: 江门
B56: 055 | C56: 众智 | D56: 陆囿霖 | E56: 13014999331 | F56: 江门
B57: 056 | C57: 鼎兴 | D57: 梁刘凤 | E57: 13828817243 | F57: 江门
B58: 057 | C58: 互蓝 | D58: 刘祖鑫 | E58: 15398166656 | F58: 江门
B59: 058 | C59: 佳鑫 | D59: 袁邦贵 | E59: 13266727239 | F59: 江门
B60: 059 | C60: 总才 | D60: 曹自亮 | E60: 19850213555 | F60: 江门
B61: 060 | C61: 贰壹贰 | D61: 沈涛 | E61: 15295195821 | F61: 江门
B62: 061 | C62: 津昌 | D62: 吴浩 | E62: 17785319564 | F62: 江门
B63: 062 | C63: 众德 | D63: 曾微微 | E63: 13070964654 | F63: 江门
B64: 063 | C64: 兄弟连 | D64: 张梓宇 | E64: 13730394924 | F64: 江门
B65: 064 | C65: 郴恒 | F65: 江门
B66: 065 | C66: 方胜 | D66: 郑甜 | E66: 17666066858 | F66: 江门
B67: 066 | C67: 小象 | F67: 江门
B68: 067 | C68: 优星图 | D68: 赵俊峰 | E68: 15617549556 | F68: 江门
B69: 068 | C69: 纳才 | F69: 江门
B70: 069 | C70: 智服 | D70: 梁仁喜 | E70: 15220757274 | F70: 江门
B71: 070 | C71: 汇天浩 | F71: 江门
B72: 071 | C72: 华志 | F72: 江门

Sheet 离职清单
A1: 序号 | B1: 姓名 | C1: 身份证后四位 | D1: 岗位类型 | E1: 技能等级 | F1: 供应商 | G1: 入职日期 | H1: 离职日期 | I1: 在职天数 | J1: 离职原因分类 | K1: 离职原因说明 | L1: 是否结算 | M1: 备注 | N1: 地区
A2: =IF(B2<>"",ROW()-1,"") -> 1 | B2: 刘江彬 | C2: 0010 | D2: 电工 | E2: 中工 | F2: 华伟 | G2: 46078 | H2: 46174 | I2: =IF(AND(G2<>"",H2<>""),H2-G2,"") -> 96 | J2: 内部管理---效率不达标 | K2: 回家有事 | L2: 是 | N2: 江门
A3: =IF(B3<>"",ROW()-1,"") -> 2 | B3: 罗春午 | C3: 0011 | D3: 电工 | E3: 中工 | F3: 慧通 | G3: 46085 | H3: 46174 | I3: =IF(AND(G3<>"",H3<>""),H3-G3,"") -> 89 | J3: 正常自离 | K3: 有事 | L3: 是 | N3: 江门
A4: =IF(B4<>"",ROW()-1,"") -> 3 | B4: 蒙庭华 | C4: 0096 | D4: 钳工 | E4: 中工 | F4: 杰威 | G4: 46102 | H4: 46174 | I4: =IF(AND(G4<>"",H4<>""),H4-G4,"") -> 72 | J4: 内部管理---效率不达标 | K4: 有事回家 | N4: 江门
A5: =IF(B5<>"",ROW()-1,"") -> 4 | B5: 黄春兰 | C5: 0097 | D5: 钳工 | E5: 小工 | F5: 聘得宝 | G5: 46105 | H5: 46174 | I5: =IF(AND(G5<>"",H5<>""),H5-G5,"") -> 69 | J5: 正常自离 | K5: 家里有事 | N5: 江门
A6: =IF(B6<>"",ROW()-1,"") -> 5 | B6: 潘新明 | C6: 0098 | D6: 钳工 | E6: 中工 | F6: 企众 | G6: 46125 | H6: 46174 | I6: =IF(AND(G6<>"",H6<>""),H6-G6,"") -> 49 | J6: 正常自离 | K6: 有事回家 | N6: 江门
A7: =IF(B7<>"",ROW()-1,"") -> 6 | B7: 李思创 | C7: 0099 | D7: 钳工 | E7: 中工 | F7: 慧通 | G7: 46126 | H7: 46174 | I7: =IF(AND(G7<>"",H7<>""),H7-G7,"") -> 48 | J7: 正常自离 | K7: 个人原因 | N7: 江门
A8: =IF(B8<>"",ROW()-1,"") -> 7 | B8: 李文亮 | C8: 0010 | D8: 仓库 | E8: 小工 | F8: 华伟 | G8: 46136 | H8: 46174 | I8: =IF(AND(G8<>"",H8<>""),H8-G8,"") -> 38 | J8: 0 | K8: 有事 | N8: 江门
A9: =IF(B9<>"",ROW()-1,"") -> 8 | B9: 李文成 | C9: 0011 | D9: 仓库 | E9: 小工 | F9: 华伟 | G9: 46136 | H9: 46174 | I9: =IF(AND(G9<>"",H9<>""),H9-G9,"") -> 38 | J9: 0 | K9: 有事回家 | N9: 江门
A10: =IF(B10<>"",ROW()-1,"") -> 9 | B10: 李自忠 | C10: 0096 | D10: 仓库 | E10: 小工 | F10: 华伟 | G10: 46136 | H10: 46174 | I10: =IF(AND(G10<>"",H10<>""),H10-G10,"") -> 38 | J10: 0 | K10: 有事 | N10: 江门
A11: =IF(B11<>"",ROW()-1,"") -> 10 | B11: 李阿清 | C11: 0097 | D11: 仓库 | E11: 小工 | F11: 华伟 | G11: 46136 | H11: 46174 | I11: =IF(AND(G11<>"",H11<>""),H11-G11,"") -> 38 | J11: 高温作业 | K11: 太热了 | N11: 江门
A12: =IF(B12<>"",ROW()-1,"") -> 11 | B12: 朱奕帆 | C12: 0098 | D12: 仓库 | E12: 小工 | F12: 智邦 | G12: 46136 | H12: 46174 | I12: =IF(AND(G12<>"",H12<>""),H12-G12,"") -> 38 | J12: 0 | K12: 因家里原因 | N12: 江门
A13: =IF(B13<>"",ROW()-1,"") -> 12 | B13: 吴洪建 | C13: 0099 | D13: 仓库 | E13: 小工 | F13: 优尔蓝 | G13: 46138 | H13: 46174 | I13: =IF(AND(G13<>"",H13<>""),H13-G13,"") -> 36 | J13: 0 | K13: 回家有事 | N13: 江门
A14: =IF(B14<>"",ROW()-1,"") -> 13 | B14: 许景忠 | C14: 0010 | D14: 钳工 | E14: 小工 | F14: 华伟 | G14: 46142 | H14: 46174 | I14: =IF(AND(G14<>"",H14<>""),H14-G14,"") -> 32 | J14: 正常自离 | K14: 有事要整理 | N14: 江门
A15: =IF(B15<>"",ROW()-1,"") -> 14 | B15: 刘以祖 | C15: 0011 | D15: 钳工 | E15: 小工 | F15: 慧城 | G15: 46143 | H15: 46174 | I15: =IF(AND(G15<>"",H15<>""),H15-G15,"") -> 31 | J15: 内部管理 | K15: 换中介 | N15: 江门
A16: =IF(B16<>"",ROW()-1,"") -> 15 | B16: 邓流旋 | C16: 0096 | D16: 钳工 | E16: 大工 | F16: 共辉 | G16: 46147 | H16: 46174 | I16: =IF(AND(G16<>"",H16<>""),H16-G16,"") -> 27 | J16: 正常自离 | K16: 回家 | N16: 江门
A17: =IF(B17<>"",ROW()-1,"") -> 16 | B17: 陈文辉 | C17: 0097 | D17: 钳工 | E17: 小工 | F17: 优尔蓝 | G17: 46148 | H17: 46174 | I17: =IF(AND(G17<>"",H17<>""),H17-G17,"") -> 26 | J17: 正常自离 | K17: 上下班通勤时间长 | N17: 江门
A18: =IF(B18<>"",ROW()-1,"") -> 17 | B18: 马尔体 | C18: 0098 | D18: 电工 | E18: 大工 | F18: 薪向往 | G18: 46149 | H18: 46174 | I18: =IF(AND(G18<>"",H18<>""),H18-G18,"") -> 25 | J18: 内部管理---效率不达标 | K18: 回家 | N18: 江门
A19: =IF(B19<>"",ROW()-1,"") -> 18 | B19: 陆河君 | C19: 0099 | D19: 钳工 | E19: 中工 | F19: 鼎兴 | G19: 46151 | H19: 46174 | I19: =IF(AND(G19<>"",H19<>""),H19-G19,"") -> 23 | J19: 正常自离 | K19: 有事回家 | N19: 江门
A20: =IF(B20<>"",ROW()-1,"") -> 19 | B20: 胡增辉 | C20: 0010 | D20: 钳工 | E20: 大工 | F20: 技为 | G20: 46154 | H20: 46174 | I20: =IF(AND(G20<>"",H20<>""),H20-G20,"") -> 20 | J20: 正常自离 | K20: 回家处理私事 | N20: 江门
A21: =IF(B21<>"",ROW()-1,"") -> 20 | B21: 罗忠明 | C21: 0011 | D21: 电工 | E21: 中工 | F21: 慧通 | G21: 46157 | H21: 46174 | I21: =IF(AND(G21<>"",H21<>""),H21-G21,"") -> 17 | J21: 正常自离 | K21: 老婆孕期要照顾 | N21: 江门
A22: =IF(B22<>"",ROW()-1,"") -> 21 | B22: 李阳信 | C22: 0096 | D22: 钳工 | E22: 小工 | F22: 聘得宝 | G22: 46157 | H22: 46174 | I22: =IF(AND(G22<>"",H22<>""),H22-G22,"") -> 17 | J22: 正常自离 | K22: 个人原因 | N22: 江门
A23: =IF(B23<>"",ROW()-1,"") -> 22 | B23: 覃淋 | C23: 0097 | D23: 仓库 | E23: 小工 | F23: 聘得宝 | G23: 46158 | H23: 46174 | I23: =IF(AND(G23<>"",H23<>""),H23-G23,"") -> 16 | J23: 0 | K23: 找到其他工作 | N23: 江门
A24: =IF(B24<>"",ROW()-1,"") -> 23 | B24: 黄丹怡 | C24: 0098 | D24: 仓库 | E24: 叉车 | F24: 聘得宝 | G24: 46161 | H24: 46174 | I24: =IF(AND(G24<>"",H24<>""),H24-G24,"") -> 13 | J24: 0 | K24: 有事 | N24: 江门
A25: =IF(B25<>"",ROW()-1,"") -> 24 | B25: 龚祚国 | C25: 0099 | D25: 钳工 | E25: 中工 | F25: 伟辉 | G25: 46163 | H25: 46174 | I25: =IF(AND(G25<>"",H25<>""),H25-G25,"") -> 11 | J25: 正常自离---不适应 | K25: 家里老人去世 | N25: 江门
A26: =IF(B26<>"",ROW()-1,"") -> 25 | B26: 农贵平 | C26: 0010 | D26: 钳工 | E26: 小工 | F26: 慧通 | G26: 46166 | H26: 46174 | I26: =IF(AND(G26<>"",H26<>""),H26-G26,"") -> 8 | J26: 内部管理---效率不达标 | K26: 被辞退 | N26: 江门
A27: =IF(B27<>"",ROW()-1,"") -> 26 | B27: 张永铨 | C27: 0011 | D27: 电工 | E27: 小工 | F27: 聘得宝 | G27: 46169 | H27: 46174 | I27: =IF(AND(G27<>"",H27<>""),H27-G27,"") -> 5 | J27: 正常自离---不适应 | K27: 个人原因 | N27: 江门
A28: =IF(B28<>"",ROW()-1,"") -> 27 | B28: 李宗顺 | C28: 0096 | D28: 仓库 | E28: 小工 | F28: 聘得宝 | G28: 46170 | H28: 46174 | I28: =IF(AND(G28<>"",H28<>""),H28-G28,"") -> 4 | J28: 0 | K28: 个人原因 | N28: 江门
A29: =IF(B29<>"",ROW()-1,"") -> 28 | B29: 王永红 | C29: 0097 | D29: 仓库 | E29: 小工 | F29: 聘得宝 | G29: 46170 | H29: 46174 | I29: =IF(AND(G29<>"",H29<>""),H29-G29,"") -> 4 | J29: 0 | K29: 回家 | N29: 江门
A30: =IF(B30<>"",ROW()-1,"") -> 29 | B30: 覃家乐 | C30: 0098 | D30: 仓库 | E30: 小工 | F30: 聘得宝 | G30: 46170 | H30: 46174 | I30: =IF(AND(G30<>"",H30<>""),H30-G30,"") -> 4 | J30: 0 | K30: 个人原因 | N30: 江门
A31: =IF(B31<>"",ROW()-1,"") -> 30 | B31: 粟尘慧 | C31: 0099 | D31: 仓库 | E31: 小工 | F31: 聘得宝 | G31: 46171 | H31: 46174 | I31: =IF(AND(G31<>"",H31<>""),H31-G31,"") -> 3 | J31: 0 | K31: 个人原因 | N31: 江门
A32: =IF(B32<>"",ROW()-1,"") -> 31 | B32: 李慧 | C32: 0010 | D32: 仓库 | E32: 叉车 | F32: 华伟 | G32: 46171 | H32: 46174 | I32: =IF(AND(G32<>"",H32<>""),H32-G32,"") -> 3 | J32: 0 | K32: 上班太远 | N32: 江门
A33: =IF(B33<>"",ROW()-1,"") -> 32 | B33: 莫军源 | C33: 0011 | D33: 仓库 | E33: 小工 | F33: 聘得宝 | G33: 46172 | H33: 46174 | I33: =IF(AND(G33<>"",H33<>""),H33-G33,"") -> 2 | J33: 0 | K33: 个人原因 | N33: 江门
A34: =IF(B34<>"",ROW()-1,"") -> 33 | B34: 陈广权 | C34: 0096 | D34: 电工 | E34: 中工 | F34: 淘金 | G34: 46163 | H34: 46174 | I34: =IF(AND(G34<>"",H34<>""),H34-G34,"") -> 11 | J34: 正常自离---不适应 | K34: 爷爷身休不好，需要回家照顾 | N34: 江门
A35: =IF(B35<>"",ROW()-1,"") -> 34 | B35: 廖百强 | C35: 0097 | D35: 电工 | E35: 中工 | F35: 慧通 | G35: 46170 | H35: 46174 | I35: =IF(AND(G35<>"",H35<>""),H35-G35,"") -> 4 | J35: 高温作业 | K35: 车间太热 | N35: 江门
A36: =IF(B36<>"",ROW()-1,"") -> 35 | B36: 梁亚东 | C36: 0098 | D36: 电工 | E36: 中工 | F36: 慧通 | G36: 46172 | H36: 46174 | I36: =IF(AND(G36<>"",H36<>""),H36-G36,"") -> 2 | J36: 高温作业 | K36: 车间太热 | N36: 江门
A37: =IF(B37<>"",ROW()-1,"") -> 36 | B37: 冯赵彬 | C37: 0099 | D37: 仓库 | E37: 小工 | F37: 聘得宝 | G37: 46155 | H37: 46174 | I37: =IF(AND(G37<>"",H37<>""),H37-G37,"") -> 19 | J37: 高温作业 | K37: 辞退 | N37: 江门
A38: =IF(B38<>"",ROW()-1,"") -> 37 | B38: 陆清波 | C38: 0010 | D38: 钳工 | E38: 小工 | F38: 技为 | G38: 46090 | H38: 46175 | I38: =IF(AND(G38<>"",H38<>""),H38-G38,"") -> 85 | J38: 正常自离 | K38: 回家有事 | N38: 江门
A39: =IF(B39<>"",ROW()-1,"") -> 38 | B39: 缪国喜 | C39: 0011 | D39: 钳工 | E39: 大工 | F39: 赞华 | G39: 46134 | H39: 46175 | I39: =IF(AND(G39<>"",H39<>""),H39-G39,"") -> 41 | J39: 高温作业 | K39: 天气热加班时间长 | N39: 江门
A40: =IF(B40<>"",ROW()-1,"") -> 39 | B40: 杨乾江 | C40: 0096 | D40: 钳工 | E40: 小工 | F40: 奕晨 | G40: 46148 | H40: 46175 | I40: =IF(AND(G40<>"",H40<>""),H40-G40,"") -> 27 | J40: 内部管理---效率不达标 | K40: 个人原因 | N40: 江门
...

Sheet 在职清单
A1: 序号 | B1: 姓名 | C1: 身份证后四位 | D1: 岗位类型 | E1: 技能等级 | F1: 供应商 | G1: 入职日期 | H1: 面试渠道 | I1: 地区 | J1: 在职天数 | K1: 当月在职天数
A2: =IF(B2<>"",ROW()-1,"") -> 1 | B2: 杨连超 | C2: =IFERROR(INDEX(面试清单!D:D,MATCH(1,面试清单!P:P,0)),"") | D2: 电工 | E2: 大工 | F2: 共辉 | G2: 45497 | H2: =IFERROR(INDEX(面试清单!H:H,MATCH(1,面试清单!P:P,0)),"") | I2: 江门 | J2: =IF(G2<>"",TODAY()-G2,"") -> 692 | K2: =IF(G2<>"",MAX(0,MIN(TODAY(),EOMONTH(TODAY(),0))-MAX(G2,EOMONTH(TODAY(),-1)+1)+1),"") -> 16
A3: =IF(B3<>"",ROW()-1,"") -> 2 | B3: 宁智国 | C3: =IFERROR(INDEX(面试清单!D:D,MATCH(2,面试清单!P:P,0)),"") | D3: 电工 | E3: 大工 | F3: 共辉 | G3: 45497 | H3: =IFERROR(INDEX(面试清单!H:H,MATCH(2,面试清单!P:P,0)),"") | I3: 江门 | J3: =IF(G3<>"",TODAY()-G3,"") -> 692 | K3: =IF(G3<>"",MAX(0,MIN(TODAY(),EOMONTH(TODAY(),0))-MAX(G3,EOMONTH(TODAY(),-1)+1)+1),"") -> 16
A4: =IF(B4<>"",ROW()-1,"") -> 3 | B4: 黄远奇 | C4: =IFERROR(INDEX(面试清单!D:D,MATCH(3,面试清单!P:P,0)),"") | D4: 电工 | E4: 大工 | F4: 共辉 | G4: 45512 | H4: =IFERROR(INDEX(面试清单!H:H,MATCH(3,面试清单!P:P,0)),"") | I4: 江门 | J4: =IF(G4<>"",TODAY()-G4,"") -> 677 | K4: =IF(G4<>"",MAX(0,MIN(TODAY(),EOMONTH(TODAY(),0))-MAX(G4,EOMONTH(TODAY(),-1)+1)+1),"") -> 16
A5: =IF(B5<>"",ROW()-1,"") -> 4 | B5: 李海 | C5: =IFERROR(INDEX(面试清单!D:D,MATCH(4,面试清单!P:P,0)),"") -> 0005 | D5: 电工 | E5: 大工 | F5: 共辉 | G5: 45513 | H5: =IFERROR(INDEX(面试清单!H:H,MATCH(4,面试清单!P:P,0)),"") -> 线下 | I5: 江门 | J5: =IF(G5<>"",TODAY()-G5,"") -> 676 | K5: =IF(G5<>"",MAX(0,MIN(TODAY(),EOMONTH(TODAY(),0))-MAX(G5,EOMONTH(TODAY(),-1)+1)+1),"") -> 16
A6: =IF(B6<>"",ROW()-1,"") -> 5 | B6: 李永利 | C6: =IFERROR(INDEX(面试清单!D:D,MATCH(5,面试清单!P:P,0)),"") -> 0006 | D6: 电工 | E6: 大工 | F6: 共辉 | G6: 45513 | H6: =IFERROR(INDEX(面试清单!H:H,MATCH(5,面试清单!P:P,0)),"") -> 线下 | I6: 江门 | J6: =IF(G6<>"",TODAY()-G6,"") -> 676 | K6: =IF(G6<>"",MAX(0,MIN(TODAY(),EOMONTH(TODAY(),0))-MAX(G6,EOMONTH(TODAY(),-1)+1)+1),"") -> 16
A7: =IF(B7<>"",ROW()-1,"") -> 6 | B7: 赵桂英 | C7: =IFERROR(INDEX(面试清单!D:D,MATCH(6,面试清单!P:P,0)),"") | D7: 电工 | E7: 大工 | F7: 共辉 | G7: 45519 | H7: =IFERROR(INDEX(面试清单!H:H,MATCH(6,面试清单!P:P,0)),"") | I7: 江门 | J7: =IF(G7<>"",TODAY()-G7,"") -> 670 | K7: =IF(G7<>"",MAX(0,MIN(TODAY(),EOMONTH(TODAY(),0))-MAX(G7,EOMONTH(TODAY(),-1)+1)+1),"") -> 16
A8: =IF(B8<>"",ROW()-1,"") -> 7 | B8: 傅伟洲 | C8: =IFERROR(INDEX(面试清单!D:D,MATCH(7,面试清单!P:P,0)),"") | D8: 电工 | E8: 大工 | F8: 共辉 | G8: 45519 | H8: =IFERROR(INDEX(面试清单!H:H,MATCH(7,面试清单!P:P,0)),"") | I8: 江门 | J8: =IF(G8<>"",TODAY()-G8,"") -> 670 | K8: =IF(G8<>"",MAX(0,MIN(TODAY(),EOMONTH(TODAY(),0))-MAX(G8,EOMONTH(TODAY(),-1)+1)+1),"") -> 16
A9: =IF(B9<>"",ROW()-1,"") -> 8 | B9: 林小军 | C9: =IFERROR(INDEX(面试清单!D:D,MATCH(8,面试清单!P:P,0)),"") -> 0009 | D9: 电工 | E9: 大工 | F9: 共辉 | G9: 45520 | H9: =IFERROR(INDEX(面试清单!H:H,MATCH(8,面试清单!P:P,0)),"") -> 线下 | I9: 江门 | J9: =IF(G9<>"",TODAY()-G9,"") -> 669 | K9: =IF(G9<>"",MAX(0,MIN(TODAY(),EOMONTH(TODAY(),0))-MAX(G9,EOMONTH(TODAY(),-1)+1)+1),"") -> 16
A10: =IF(B10<>"",ROW()-1,"") -> 9 | B10: 赵国阳 | C10: =IFERROR(INDEX(面试清单!D:D,MATCH(9,面试清单!P:P,0)),"") | D10: 电工 | E10: 大工 | F10: 共辉 | G10: 45523 | H10: =IFERROR(INDEX(面试清单!H:H,MATCH(9,面试清单!P:P,0)),"") | I10: 江门 | J10: =IF(G10<>"",TODAY()-G10,"") -> 666 | K10: =IF(G10<>"",MAX(0,MIN(TODAY(),EOMONTH(TODAY(),0))-MAX(G10,EOMONTH(TODAY(),-1)+1)+1),"") -> 16
A11: =IF(B11<>"",ROW()-1,"") -> 10 | B11: 陈车喜 | C11: =IFERROR(INDEX(面试清单!D:D,MATCH(10,面试清单!P:P,0)),"") -> 0013 | D11: 钳工 | E11: 大工 | F11: 聚宏 | G11: 45537 | H11: =IFERROR(INDEX(面试清单!H:H,MATCH(10,面试清单!P:P,0)),"") -> 线下 | I11: 江门 | J11: =IF(G11<>"",TODAY()-G11,"") -> 652 | K11: =IF(G11<>"",MAX(0,MIN(TODAY(),EOMONTH(TODAY(),0))-MAX(G11,EOMONTH(TODAY(),-1)+1)+1),"") -> 16
A12: =IF(B12<>"",ROW()-1,"") -> 11 | B12: 郑锦铭 | C12: =IFERROR(INDEX(面试清单!D:D,MATCH(11,面试清单!P:P,0)),"") | D12: 电工 | E12: 大工 | F12: 慧城 | G12: 45544 | H12: =IFERROR(INDEX(面试清单!H:H,MATCH(11,面试清单!P:P,0)),"") | I12: 江门 | J12: =IF(G12<>"",TODAY()-G12,"") -> 645 | K12: =IF(G12<>"",MAX(0,MIN(TODAY(),EOMONTH(TODAY(),0))-MAX(G12,EOMONTH(TODAY(),-1)+1)+1),"") -> 16
A13: =IF(B13<>"",ROW()-1,"") -> 12 | B13: 叶昌福 | C13: =IFERROR(INDEX(面试清单!D:D,MATCH(12,面试清单!P:P,0)),"") | D13: 电工 | E13: 大工 | F13: 共辉 | G13: 45546 | H13: =IFERROR(INDEX(面试清单!H:H,MATCH(12,面试清单!P:P,0)),"") | I13: 江门 | J13: =IF(G13<>"",TODAY()-G13,"") -> 643 | K13: =IF(G13<>"",MAX(0,MIN(TODAY(),EOMONTH(TODAY(),0))-MAX(G13,EOMONTH(TODAY(),-1)+1)+1),"") -> 16
A14: =IF(B14<>"",ROW()-1,"") -> 13 | B14: 杨祖标 | C14: =IFERROR(INDEX(面试清单!D:D,MATCH(13,面试清单!P:P,0)),"") | D14: 电工 | E14: 大工 | F14: 奕晨 | G14: 45553 | H14: =IFERROR(INDEX(面试清单!H:H,MATCH(13,面试清单!P:P,0)),"") | I14: 江门 | J14: =IF(G14<>"",TODAY()-G14,"") -> 636 | K14: =IF(G14<>"",MAX(0,MIN(TODAY(),EOMONTH(TODAY(),0))-MAX(G14,EOMONTH(TODAY(),-1)+1)+1),"") -> 16
A15: =IF(B15<>"",ROW()-1,"") -> 14 | B15: 陈凤文 | C15: =IFERROR(INDEX(面试清单!D:D,MATCH(14,面试清单!P:P,0)),"") | D15: 电工 | E15: 大工 | F15: 科为 | G15: 45554 | H15: =IFERROR(INDEX(面试清单!H:H,MATCH(14,面试清单!P:P,0)),"") | I15: 江门 | J15: =IF(G15<>"",TODAY()-G15,"") -> 635 | K15: =IF(G15<>"",MAX(0,MIN(TODAY(),EOMONTH(TODAY(),0))-MAX(G15,EOMONTH(TODAY(),-1)+1)+1),"") -> 16
A16: =IF(B16<>"",ROW()-1,"") -> 15 | B16: 李文1 | C16: =IFERROR(INDEX(面试清单!D:D,MATCH(15,面试清单!P:P,0)),"") | D16: 电工 | E16: 大工 | F16: 共辉 | G16: 45560 | H16: =IFERROR(INDEX(面试清单!H:H,MATCH(15,面试清单!P:P,0)),"") | I16: 江门 | J16: =IF(G16<>"",TODAY()-G16,"") -> 629 | K16: =IF(G16<>"",MAX(0,MIN(TODAY(),EOMONTH(TODAY(),0))-MAX(G16,EOMONTH(TODAY(),-1)+1)+1),"") -> 16
A17: =IF(B17<>"",ROW()-1,"") -> 16 | B17: 宾楚锐 | C17: =IFERROR(INDEX(面试清单!D:D,MATCH(16,面试清单!P:P,0)),"") | D17: 电工 | E17: 大工 | F17: 领冠 | G17: 45580 | H17: =IFERROR(INDEX(面试清单!H:H,MATCH(16,面试清单!P:P,0)),"") | I17: 江门 | J17: =IF(G17<>"",TODAY()-G17,"") -> 609 | K17: =IF(G17<>"",MAX(0,MIN(TODAY(),EOMONTH(TODAY(),0))-MAX(G17,EOMONTH(TODAY(),-1)+1)+1),"") -> 16
A18: =IF(B18<>"",ROW()-1,"") -> 17 | B18: 谢昌宏 | C18: =IFERROR(INDEX(面试清单!D:D,MATCH(17,面试清单!P:P,0)),"") -> 0020 | D18: 钳工 | E18: 大工 | F18: 科为 | G18: 45597 | H18: =IFERROR(INDEX(面试清单!H:H,MATCH(17,面试清单!P:P,0)),"") -> 线下 | I18: 江门 | J18: =IF(G18<>"",TODAY()-G18,"") -> 592 | K18: =IF(G18<>"",MAX(0,MIN(TODAY(),EOMONTH(TODAY(),0))-MAX(G18,EOMONTH(TODAY(),-1)+1)+1),"") -> 16
A19: =IF(B19<>"",ROW()-1,"") -> 18 | B19: 姚武锋 | C19: =IFERROR(INDEX(面试清单!D:D,MATCH(18,面试清单!P:P,0)),"") | D19: 电工 | E19: 大工 | F19: 共辉 | G19: 45614 | H19: =IFERROR(INDEX(面试清单!H:H,MATCH(18,面试清单!P:P,0)),"") | I19: 江门 | J19: =IF(G19<>"",TODAY()-G19,"") -> 575 | K19: =IF(G19<>"",MAX(0,MIN(TODAY(),EOMONTH(TODAY(),0))-MAX(G19,EOMONTH(TODAY(),-1)+1)+1),"") -> 16
A20: =IF(B20<>"",ROW()-1,"") -> 19 | B20: 杨伟 | C20: =IFERROR(INDEX(面试清单!D:D,MATCH(19,面试清单!P:P,0)),"") | D20: 电工 | E20: 大工 | F20: 奕晨 | G20: 45617 | H20: =IFERROR(INDEX(面试清单!H:H,MATCH(19,面试清单!P:P,0)),"") | I20: 江门 | J20: =IF(G20<>"",TODAY()-G20,"") -> 572 | K20: =IF(G20<>"",MAX(0,MIN(TODAY(),EOMONTH(TODAY(),0))-MAX(G20,EOMONTH(TODAY(),-1)+1)+1),"") -> 16
A21: =IF(B21<>"",ROW()-1,"") -> 20 | B21: 祝立 | C21: =IFERROR(INDEX(面试清单!D:D,MATCH(20,面试清单!P:P,0)),"") | D21: 电工 | E21: 大工 | F21: 慧通 | G21: 45618 | H21: =IFERROR(INDEX(面试清单!H:H,MATCH(20,面试清单!P:P,0)),"") | I21: 江门 | J21: =IF(G21<>"",TODAY()-G21,"") -> 571 | K21: =IF(G21<>"",MAX(0,MIN(TODAY(),EOMONTH(TODAY(),0))-MAX(G21,EOMONTH(TODAY(),-1)+1)+1),"") -> 16
A22: =IF(B22<>"",ROW()-1,"") -> 21 | B22: 彭罗金 | C22: =IFERROR(INDEX(面试清单!D:D,MATCH(21,面试清单!P:P,0)),"") | D22: 电工 | E22: 大工 | F22: 慧城 | G22: 45621 | H22: =IFERROR(INDEX(面试清单!H:H,MATCH(21,面试清单!P:P,0)),"") | I22: 江门 | J22: =IF(G22<>"",TODAY()-G22,"") -> 568 | K22: =IF(G22<>"",MAX(0,MIN(TODAY(),EOMONTH(TODAY(),0))-MAX(G22,EOMONTH(TODAY(),-1)+1)+1),"") -> 16
A23: =IF(B23<>"",ROW()-1,"") -> 22 | B23: 杨明善 | C23: =IFERROR(INDEX(面试清单!D:D,MATCH(22,面试清单!P:P,0)),"") | D23: 电工 | E23: 大工 | F23: 慧城 | G23: 45621 | H23: =IFERROR(INDEX(面试清单!H:H,MATCH(22,面试清单!P:P,0)),"") | I23: 江门 | J23: =IF(G23<>"",TODAY()-G23,"") -> 568 | K23: =IF(G23<>"",MAX(0,MIN(TODAY(),EOMONTH(TODAY(),0))-MAX(G23,EOMONTH(TODAY(),-1)+1)+1),"") -> 16
A24: =IF(B24<>"",ROW()-1,"") -> 23 | B24: 帅祥辉 | C24: =IFERROR(INDEX(面试清单!D:D,MATCH(23,面试清单!P:P,0)),"") | D24: 电工 | E24: 大工 | F24: 共辉 | G24: 45621 | H24: =IFERROR(INDEX(面试清单!H:H,MATCH(23,面试清单!P:P,0)),"") | I24: 江门 | J24: =IF(G24<>"",TODAY()-G24,"") -> 568 | K24: =IF(G24<>"",MAX(0,MIN(TODAY(),EOMONTH(TODAY(),0))-MAX(G24,EOMONTH(TODAY(),-1)+1)+1),"") -> 16
A25: 24 | B25: 甘家成 | C25: 0027 | D25: 电工 | E25: 大工 | F25: 共辉 | G25: 45621 | H25: 线上 | I25: 江门 | J25: 15 | K25: 16
A26: =IF(B26<>"",ROW()-1,"") -> 25 | B26: 蔡昌贵 | C26: =IFERROR(INDEX(面试清单!D:D,MATCH(25,面试清单!P:P,0)),"") | D26: 电工 | E26: 大工 | F26: 聘得宝 | G26: 45643 | H26: =IFERROR(INDEX(面试清单!H:H,MATCH(25,面试清单!P:P,0)),"") | I26: 江门 | J26: =IF(G26<>"",TODAY()-G26,"") -> 546 | K26: =IF(G26<>"",MAX(0,MIN(TODAY(),EOMONTH(TODAY(),0))-MAX(G26,EOMONTH(TODAY(),-1)+1)+1),"") -> 16
A27: =IF(B27<>"",ROW()-1,"") -> 26 | B27: 姚熙 | C27: =IFERROR(INDEX(面试清单!D:D,MATCH(26,面试清单!P:P,0)),"") | D27: 钳工 | E27: 大工 | F27: 共辉 | G27: 45658 | H27: =IFERROR(INDEX(面试清单!H:H,MATCH(26,面试清单!P:P,0)),"") | I27: 江门 | J27: =IF(G27<>"",TODAY()-G27,"") -> 531 | K27: =IF(G27<>"",MAX(0,MIN(TODAY(),EOMONTH(TODAY(),0))-MAX(G27,EOMONTH(TODAY(),-1)+1)+1),"") -> 16
A28: =IF(B28<>"",ROW()-1,"") -> 27 | B28: 邓国坚 | C28: =IFERROR(INDEX(面试清单!D:D,MATCH(27,面试清单!P:P,0)),"") -> 0030 | D28: 电工 | E28: 大工 | F28: 伟辉 | G28: 45660 | H28: =IFERROR(INDEX(面试清单!H:H,MATCH(27,面试清单!P:P,0)),"") -> 线下 | I28: 江门 | J28: =IF(G28<>"",TODAY()-G28,"") -> 529 | K28: =IF(G28<>"",MAX(0,MIN(TODAY(),EOMONTH(TODAY(),0))-MAX(G28,EOMONTH(TODAY(),-1)+1)+1),"") -> 16
A29: =IF(B29<>"",ROW()-1,"") -> 28 | B29: 代伟伟 | C29: =IFERROR(INDEX(面试清单!D:D,MATCH(28,面试清单!P:P,0)),"") | D29: 电工 | E29: 大工 | F29: 慧通 | G29: 45696 | H29: =IFERROR(INDEX(面试清单!H:H,MATCH(28,面试清单!P:P,0)),"") | I29: 江门 | J29: =IF(G29<>"",TODAY()-G29,"") -> 493 | K29: =IF(G29<>"",MAX(0,MIN(TODAY(),EOMONTH(TODAY(),0))-MAX(G29,EOMONTH(TODAY(),-1)+1)+1),"") -> 16
A30: =IF(B30<>"",ROW()-1,"") -> 29 | B30: 黄文伟 | C30: =IFERROR(INDEX(面试清单!D:D,MATCH(29,面试清单!P:P,0)),"") | D30: 电工 | E30: 大工 | F30: 聘得宝 | G30: 45696 | H30: =IFERROR(INDEX(面试清单!H:H,MATCH(29,面试清单!P:P,0)),"") | I30: 江门 | J30: =IF(G30<>"",TODAY()-G30,"") -> 493 | K30: =IF(G30<>"",MAX(0,MIN(TODAY(),EOMONTH(TODAY(),0))-MAX(G30,EOMONTH(TODAY(),-1)+1)+1),"") -> 16
A31: =IF(B31<>"",ROW()-1,"") -> 30 | B31: 覃开树 | C31: =IFERROR(INDEX(面试清单!D:D,MATCH(30,面试清单!P:P,0)),"") -> 0033 | D31: 电工 | E31: 大工 | F31: 慧通 | G31: 45698 | H31: =IFERROR(INDEX(面试清单!H:H,MATCH(30,面试清单!P:P,0)),"") -> 线下 | I31: 江门 | J31: =IF(G31<>"",TODAY()-G31,"") -> 491 | K31: =IF(G31<>"",MAX(0,MIN(TODAY(),EOMONTH(TODAY(),0))-MAX(G31,EOMONTH(TODAY(),-1)+1)+1),"") -> 16
A32: =IF(B32<>"",ROW()-1,"") -> 31 | B32: 唐华冰 | C32: =IFERROR(INDEX(面试清单!D:D,MATCH(31,面试清单!P:P,0)),"") | D32: 电工 | E32: 大工 | F32: 慧通 | G32: 45698 | H32: =IFERROR(INDEX(面试清单!H:H,MATCH(31,面试清单!P:P,0)),"") | I32: 江门 | J32: =IF(G32<>"",TODAY()-G32,"") -> 491 | K32: =IF(G32<>"",MAX(0,MIN(TODAY(),EOMONTH(TODAY(),0))-MAX(G32,EOMONTH(TODAY(),-1)+1)+1),"") -> 16
A33: =IF(B33<>"",ROW()-1,"") -> 32 | B33: 卢仕满 | C33: =IFERROR(INDEX(面试清单!D:D,MATCH(32,面试清单!P:P,0)),"") | D33: 钳工 | E33: 大工 | F33: 聘得宝 | G33: 45698 | H33: =IFERROR(INDEX(面试清单!H:H,MATCH(32,面试清单!P:P,0)),"") | I33: 江门 | J33: =IF(G33<>"",TODAY()-G33,"") -> 491 | K33: =IF(G33<>"",MAX(0,MIN(TODAY(),EOMONTH(TODAY(),0))-MAX(G33,EOMONTH(TODAY(),-1)+1)+1),"") -> 16
A34: =IF(B34<>"",ROW()-1,"") -> 33 | B34: 雷绍坚 | C34: =IFERROR(INDEX(面试清单!D:D,MATCH(33,面试清单!P:P,0)),"") | D34: 钳工 | E34: 大工 | F34: 聘得宝 | G34: 45701 | H34: =IFERROR(INDEX(面试清单!H:H,MATCH(33,面试清单!P:P,0)),"") | I34: 江门 | J34: =IF(G34<>"",TODAY()-G34,"") -> 488 | K34: =IF(G34<>"",MAX(0,MIN(TODAY(),EOMONTH(TODAY(),0))-MAX(G34,EOMONTH(TODAY(),-1)+1)+1),"") -> 16
A35: =IF(B35<>"",ROW()-1,"") -> 34 | B35: 袁明飞 | C35: =IFERROR(INDEX(面试清单!D:D,MATCH(34,面试清单!P:P,0)),"") | D35: 钳工 | E35: 大工 | F35: 共辉 | G35: 45701 | H35: =IFERROR(INDEX(面试清单!H:H,MATCH(34,面试清单!P:P,0)),"") | I35: 江门 | J35: =IF(G35<>"",TODAY()-G35,"") -> 488 | K35: =IF(G35<>"",MAX(0,MIN(TODAY(),EOMONTH(TODAY(),0))-MAX(G35,EOMONTH(TODAY(),-1)+1)+1),"") -> 16
A36: =IF(B36<>"",ROW()-1,"") -> 35 | B36: 刘伟1 | C36: =IFERROR(INDEX(面试清单!D:D,MATCH(35,面试清单!P:P,0)),"") | D36: 电工 | E36: 大工 | F36: 聘得宝 | G36: 45703 | H36: =IFERROR(INDEX(面试清单!H:H,MATCH(35,面试清单!P:P,0)),"") | I36: 江门 | J36: =IF(G36<>"",TODAY()-G36,"") -> 486 | K36: =IF(G36<>"",MAX(0,MIN(TODAY(),EOMONTH(TODAY(),0))-MAX(G36,EOMONTH(TODAY(),-1)+1)+1),"") -> 16
A37: =IF(B37<>"",ROW()-1,"") -> 36 | B37: 周长辉 | C37: =IFERROR(INDEX(面试清单!D:D,MATCH(36,面试清单!P:P,0)),"") | D37: 钳工 | E37: 大工 | F37: 聘得宝 | G37: 45703 | H37: =IFERROR(INDEX(面试清单!H:H,MATCH(36,面试清单!P:P,0)),"") | I37: 江门 | J37: =IF(G37<>"",TODAY()-G37,"") -> 486 | K37: =IF(G37<>"",MAX(0,MIN(TODAY(),EOMONTH(TODAY(),0))-MAX(G37,EOMONTH(TODAY(),-1)+1)+1),"") -> 16
A38: =IF(B38<>"",ROW()-1,"") -> 37 | B38: 叶永乾 | C38: =IFERROR(INDEX(面试清单!D:D,MATCH(37,面试清单!P:P,0)),"") | D38: 电工 | E38: 大工 | F38: 共辉 | G38: 45705 | H38: =IFERROR(INDEX(面试清单!H:H,MATCH(37,面试清单!P:P,0)),"") | I38: 江门 | J38: =IF(G38<>"",TODAY()-G38,"") -> 484 | K38: =IF(G38<>"",MAX(0,MIN(TODAY(),EOMONTH(TODAY(),0))-MAX(G38,EOMONTH(TODAY(),-1)+1)+1),"") -> 16
A39: =IF(B39<>"",ROW()-1,"") -> 38 | B39: 张文静 | C39: =IFERROR(INDEX(面试清单!D:D,MATCH(38,面试清单!P:P,0)),"") | D39: 电工 | E39: 大工 | F39: 共辉 | G39: 45705 | H39: =IFERROR(INDEX(面试清单!H:H,MATCH(38,面试清单!P:P,0)),"") | I39: 江门 | J39: =IF(G39<>"",TODAY()-G39,"") -> 484 | K39: =IF(G39<>"",MAX(0,MIN(TODAY(),EOMONTH(TODAY(),0))-MAX(G39,EOMONTH(TODAY(),-1)+1)+1),"") -> 16
A40: =IF(B40<>"",ROW()-1,"") -> 39 | B40: 唐宗贵 | C40: =IFERROR(INDEX(面试清单!D:D,MATCH(39,面试清单!P:P,0)),"") | D40: 电工 | E40: 大工 | F40: 共辉 | G40: 45706 | H40: =IFERROR(INDEX(面试清单!H:H,MATCH(39,面试清单!P:P,0)),"") | I40: 江门 | J40: =IF(G40<>"",TODAY()-G40,"") -> 483 | K40: =IF(G40<>"",MAX(0,MIN(TODAY(),EOMONTH(TODAY(),0))-MAX(G40,EOMONTH(TODAY(),-1)+1)+1),"") -> 16
...

Sheet 使用说明
B1: 临时工管理台账 — 使用说明（v3）
B3: 一、文件概览
B4: 本文件共包含 6 个工作表：
B5: Sheet 1「面试清单」— 数据入口，录入所有面试候选人（绿色单元格为可填写）
B6: Sheet 2「离职清单」— 数据入口，记录离职事件（绿色单元格为可填写，其余自动VLOOKUP拉取）
B7: Sheet 3「在职清单」— 自动生成，无需手动操作
B8: Sheet 4「供应商管理」— 维护供应商列表，面试清单下拉菜单自动引用此表
B9: Sheet 5「指标看板」— KPI + 总目标表 + 周日度明细 + 人员结构分析 + 渠道对比 + 周度图表
B10: Sheet 6「使用说明」— 即本页
B12: 二、日常操作流程
B13: 步骤1: 维护供应商 → 打开「供应商管理」，填写供应商编号和名称（已预填001~003示例）
B14: 步骤2: 有人来面试 → 打开「面试清单」，填写一行（日期、姓名、身份证后四位、岗位、等级、供应商、渠道、结果、地区）
... B70: 6. 周日度明细表默认展示7天，如需更多天数请修改脚本中的 num_days 变量
